<?xml version="1.0" encoding="utf-8"  ?>
<robot name="ball">
	<!-- * * * Link Definitions * * * -->
  	<!-- * * * Define World Link to fix the foot rail to the world * * * -->
    <link name="world"/>
	<link name="ball">
		<visual>
			<origin xyz="0 0 0" rpy="0 0 0"/>
			<geometry>
				<sphere radius="0.5"/>
			</geometry>
	   </visual>
		<collision>
			<origin xyz="0 0 0" rpy="0 0 0"/>
			<geometry>
				<sphere radius="0.5"/>
			</geometry>
	   </collision>

		<inertial>
			<origin xyz="0 0 0" rpy="0 0 0"/>
			<mass value="1" />
			<inertia ixx="0.2" ixy="0.0" ixz="0.0" iyy="0.2" iyz="0.0" izz="0.2"/>
		</inertial>
	</link>
	<joint name="joint" type="floating">
        <parent link="world"/>
        <child link="ball"/>
    </joint>
</robot>
